<?xml version="1.0" ?>
<!-- =================================================================================== -->
<!-- |    This document was autogenerated by xacro from jackdaw.urdf.xacro             | -->
<!-- |    EDITING THIS FILE BY HAND IS NOT RECOMMENDED                                 | -->
<!-- =================================================================================== -->
<robot name="jackdaw_arm">
  <material name="darkgray">
    <color rgba="0.3 0.3 0.3 1.0"/>
  </material>
  <material name="gray">
    <color rgba="0.5 0.5 0.5 1.0"/>
  </material>
  <material name="black">
    <color rgba="0.0 0.0 0.0 1.0"/>
  </material>
  <material name="yellow">
    <color rgba="1.0 1.0 0.0 1.0"/>
  </material>
  <link name="base_link">
    <visual>
      <origin rpy="0 0 0" xyz="0 0 0"/>
      <material name="darkgray"/>
      <geometry>
        <cylinder length="0.15" radius="0.15"/>
      </geometry>
    </visual>
    <collision>
      <origin rpy="0 0 0" xyz="0 0 0"/>
      <geometry>
        <cylinder length="0.15" radius="0.15"/>
      </geometry>
    </collision>
    <inertial>
      <origin rpy="0 0 0" xyz="0 0 0"/>
      <mass value="20"/>
      <inertia ixx="1.0" ixy="0.0" ixz="0.0" iyy="1.0" iyz="0.0" izz="1.0"/>
    </inertial>
  </link>
  <joint name="base_rotational_joint" type="continuous">
    <parent link="base_link"/>
    <child link="link_one"/>
    <origin rpy="0 0 0" xyz="0 0 0.075"/>
    <axis xyz="0 0 1"/>
  </joint>
  <link name="link_one">
    <visual>
      <origin rpy="0 0 0" xyz="0 0.060000000000000005 0.125"/>
      <material name="darkgray"/>
      <geometry>
        <box size="0.1 0.05 0.25"/>
      </geometry>
    </visual>
    <collision>
      <origin rpy="0 0 0" xyz="0 0.060000000000000005 0.125"/>
      <geometry>
        <box size="0.1 0.05 0.25"/>
      </geometry>
    </collision>
    <inertial>
      <origin rpy="0 0 0" xyz="0 0.060000000000000005 0.125"/>
      <mass value="2"/>
      <inertia ixx="1.0" ixy="0.0" ixz="0.0" iyy="1.0" iyz="0.0" izz="1.0"/>
    </inertial>
  </link>
  <joint name="shoulder_joint" type="revolute">
    <parent link="link_one"/>
    <child link="link_two"/>
    <origin rpy="0 0 0" xyz="0 0 0.125"/>
    <axis xyz="0 1 0"/>
    <limit effort="10" lower="-1.570796325" upper="1.570796325" velocity="1.570796325"/>
  </joint>
  <link name="link_two">
    <visual>
      <origin rpy="0 0 0" xyz="0 0 0.3"/>
      <material name="gray"/>
      <geometry>
        <box size="0.07 0.07 0.6"/>
      </geometry>
    </visual>
    <collision>
      <origin rpy="0 0 0" xyz="0 0 0.3"/>
      <geometry>
        <box size="0.07 0.07 0.6"/>
      </geometry>
    </collision>
    <inertial>
      <origin rpy="0 0 0" xyz="0 0 0.3"/>
      <mass value="4"/>
      <inertia ixx="1.0" ixy="0.0" ixz="0.0" iyy="1.0" iyz="0.0" izz="1.0"/>
    </inertial>
  </link>
  <joint name="elbow_joint" type="continuous">
    <parent link="link_two"/>
    <child link="link_three"/>
    <origin rpy="0 0 0" xyz="0 0 0.6"/>
    <axis xyz="0 1 0"/>
    <limit effort="10" lower="-2.3561944875000003" upper="2.3561944875000003" velocity="1.570796325"/>
  </joint>
  <link name="link_three">
    <visual>
      <origin rpy="0 0 0" xyz="0 0.07 0.3"/>
      <material name="gray"/>
      <geometry>
        <box size="0.07 0.07 0.6"/>
      </geometry>
    </visual>
    <collision>
      <origin rpy="0 0 0" xyz="0 0.07 0.3"/>
      <geometry>
        <box size="0.07 0.07 0.6"/>
      </geometry>
    </collision>
    <inertial>
      <origin rpy="0 0 0" xyz="0 0.07 0.3"/>
      <mass value="4"/>
      <inertia ixx="1.0" ixy="0.0" ixz="0.0" iyy="1.0" iyz="0.0" izz="1.0"/>
    </inertial>
  </link>
  <joint name="wrist_joint_rot" type="continuous">
    <parent link="link_three"/>
    <child link="link_four"/>
    <origin rpy="0 0 0" xyz="0 0 0.6"/>
    <axis xyz="0 1 0"/>
    <limit effort="10" lower="-2.3561944875000003" upper="2.3561944875000003" velocity="1.570796325"/>
  </joint>
  <link name="link_four">
    <visual>
      <origin rpy="0 0 0" xyz="0 0 0.1"/>
      <material name="gray"/>
      <geometry>
        <box size="0.07 0.07 0.2"/>
      </geometry>
    </visual>
    <collision>
      <origin rpy="0 0 0" xyz="0 0 0.1"/>
      <geometry>
        <box size="0.07 0.07 0.2"/>
      </geometry>
    </collision>
    <inertial>
      <origin rpy="0 0 0" xyz="0 0 0.1"/>
      <mass value="2"/>
      <inertia ixx="1.0" ixy="0.0" ixz="0.0" iyy="1.0" iyz="0.0" izz="1.0"/>
    </inertial>
  </link>
  <joint name="wrist_joint" type="continuous">
    <parent link="link_four"/>
    <child link="wrist"/>
    <origin rpy="0 0 0" xyz="0 0 0.2"/>
    <axis xyz="0 0 1"/>
  </joint>
  <link name="wrist">
    <visual>
      <origin rpy="0 0 0" xyz="0 0 0.015"/>
      <material name="black"/>
      <geometry>
        <cylinder length="0.03" radius="0.05"/>
      </geometry>
    </visual>
    <collision>
      <origin rpy="0 0 0" xyz="0 0 0.015"/>
      <geometry>
        <cylinder length="0.03" radius="0.05"/>
      </geometry>
    </collision>
    <inertial>
      <origin rpy="0 0 0" xyz="0 0 0.015"/>
      <mass value="1"/>
      <inertia ixx="1.0" ixy="0.0" ixz="0.0" iyy="1.0" iyz="0.0" izz="1.0"/>
    </inertial>
  </link>
  <joint name="gripper_joint" type="fixed">
    <parent link="wrist"/>
    <child link="gripper"/>
    <origin rpy="0 0 0" xyz="0 0 0.03"/>
  </joint>
  <link name="gripper">
    <visual>
      <origin rpy="0 0 0" xyz="0 0 0.025"/>
      <material name="yellow"/>
      <geometry>
        <box size="0.2 0.3 0.05"/>
      </geometry>
    </visual>
    <collision>
      <origin rpy="0 0 0" xyz="0 0 0.025"/>
      <geometry>
        <box size="0.2 0.3 0.05"/>
      </geometry>
    </collision>
    <inertial>
      <origin rpy="0 0 0" xyz="0 0 0.025"/>
      <mass value="2"/>
      <inertia ixx="1.0" ixy="0.0" ixz="0.0" iyy="1.0" iyz="0.0" izz="1.0"/>
    </inertial>
  </link>
  <!-- CYLS -->
  <joint name="shoulder_cyl" type="fixed">
    <parent link="link_two"/>
    <child link="cyl_one"/>
    <origin rpy="0 0 0" xyz="0 0 0"/>
  </joint>
  <link name="cyl_one">
    <visual>
      <origin rpy="1.570796325 0 0" xyz="0 0 0"/>
      <material name="black"/>
      <geometry>
        <cylinder length="0.09000000000000001" radius="0.07"/>
      </geometry>
    </visual>
    <inertial>
      <origin rpy="1.570796325 0 0" xyz="0 0 0"/>
      <mass value="1"/>
      <inertia ixx="1.0" ixy="0.0" ixz="0.0" iyy="1.0" iyz="0.0" izz="1.0"/>
    </inertial>
  </link>
  <joint name="elbow_cyl" type="fixed">
    <parent link="link_three"/>
    <child link="cyl_two"/>
    <origin rpy="0 0 0" xyz="0 0 0"/>
  </joint>
  <link name="cyl_two">
    <visual>
      <origin rpy="1.570796325 0 0" xyz="0 0.035 0"/>
      <material name="black"/>
      <geometry>
        <cylinder length="0.16" radius="0.07"/>
      </geometry>
    </visual>
    <inertial>
      <origin rpy="1.570796325 0 0" xyz="0 0.035 0"/>
      <mass value="1"/>
      <inertia ixx="1.0" ixy="0.0" ixz="0.0" iyy="1.0" iyz="0.0" izz="1.0"/>
    </inertial>
  </link>
  <joint name="wrist_cyl" type="fixed">
    <parent link="link_four"/>
    <child link="cyl_three"/>
    <origin rpy="0 0 0" xyz="0 0 0"/>
  </joint>
  <link name="cyl_three">
    <visual>
      <origin rpy="1.570796325 0 0" xyz="0 0.035 0"/>
      <material name="black"/>
      <geometry>
        <cylinder length="0.16" radius="0.07"/>
      </geometry>
    </visual>
    <inertial>
      <origin rpy="1.570796325 0 0" xyz="0 0.035 0"/>
      <mass value="1"/>
      <inertia ixx="1.0" ixy="0.0" ixz="0.0" iyy="1.0" iyz="0.0" izz="1.0"/>
    </inertial>
  </link>
  <gazebo reference="base_link">
    <material>Gazebo/DarkGrey</material>
  </gazebo>
  <gazebo reference="link_one">
    <material>Gazebo/DarkGrey</material>
  </gazebo>
  <gazebo reference="link_two">
    <material>Gazebo/Grey</material>
  </gazebo>
  <gazebo reference="link_three">
    <material>Gazebo/Grey</material>
  </gazebo>
  <gazebo reference="link_four">
    <material>Gazebo/Grey</material>
  </gazebo>
  <gazebo reference="cyl_one">
    <material>Gazebo/FlatBlack</material>
  </gazebo>
  <gazebo reference="cyl_two">
    <material>Gazebo/FlatBlack</material>
  </gazebo>
  <gazebo reference="cyl_three">
    <material>Gazebo/FlatBlack</material>
  </gazebo>
  <gazebo reference="wrist">
    <material>Gazebo/FlatBlack</material>
  </gazebo>
  <gazebo reference="gripper">
    <material>Gazebo/ZincYellow</material>
  </gazebo>
</robot>
